# Error Management Rules

## Accumulate Multiple Errors with Either
**Rule:** Use Either to accumulate multiple validation errors instead of failing on the first one.

### Example
Using `Schema.decode` with the `allErrors: true` option demonstrates this pattern perfectly. The underlying mechanism uses `Either` to collect all parsing errors into an array instead of stopping at the first one.

````typescript
import { Effect, Schema, Data } from "effect";

// Define validation error type
class ValidationError extends Data.TaggedError("ValidationError")<{
  readonly field: string;
  readonly message: string;
}> {}

// Define user type
type User = {
  name: string;
  email: string;
};

// Define schema with custom validation
const UserSchema = Schema.Struct({
  name: Schema.String.pipe(
    Schema.minLength(3),
    Schema.filter((name) => /^[A-Za-z\s]+$/.test(name), {
      message: () => "name must contain only letters and spaces"
    })
  ),
  email: Schema.String.pipe(
    Schema.pattern(/@/),
    Schema.pattern(/^[^\s@]+@[^\s@]+\.[^\s@]+$/, {
      message: () => "email must be a valid email address"
    })
  ),
});

// Example inputs
const invalidInputs: User[] = [
  {
    name: "Al", // Too short
    email: "bob-no-at-sign.com", // Invalid pattern
  },
  {
    name: "John123", // Contains numbers
    email: "john@incomplete", // Invalid email
  },
  {
    name: "Alice Smith", // Valid
    email: "alice@example.com", // Valid
  }
];

// Validate a single user
const validateUser = (input: User) =>
  Effect.gen(function* () {
    const result = yield* Schema.decode(UserSchema)(input, { errors: "all" });
    return result;
  });

// Process multiple users and accumulate all errors
const program = Effect.gen(function* () {
  console.log("Validating users...\n");
  
  for (const input of invalidInputs) {
    const result = yield* Effect.either(validateUser(input));
    
    console.log(`Validating user: ${input.name} <${input.email}>`);
    
    yield* Effect.match(result, {
      onFailure: (error) => Effect.sync(() => {
        console.log("❌ Validation failed:");
        console.log(error.message);
        console.log(); // Empty line for readability
      }),
      onSuccess: (user) => Effect.sync(() => {
        console.log("✅ User is valid:", user);
        console.log(); // Empty line for readability
      })
    });
  }
});

// Run the program
Effect.runSync(program);
````

---

## Conditionally Branching Workflows
**Rule:** Use predicate-based operators like Effect.filter and Effect.if to declaratively control workflow branching.

### Example
Here, we use `Effect.filter` with named predicates to validate a user before proceeding. The intent is crystal clear, and the business rules (`isActive`, `isAdmin`) are reusable.

```typescript
import { Effect } from "effect";

interface User {
  id: number;
  status: "active" | "inactive";
  roles: string[];
}

type UserError = "DbError" | "UserIsInactive" | "UserIsNotAdmin";

const findUser = (id: number): Effect.Effect<User, "DbError"> =>
  Effect.succeed({ id, status: "active", roles: ["admin"] });

// Reusable, testable predicates that document business rules.
const isActive = (user: User): Effect.Effect<boolean> =>
  Effect.succeed(user.status === "active");

const isAdmin = (user: User): Effect.Effect<boolean> =>
  Effect.succeed(user.roles.includes("admin"));

const program = (id: number): Effect.Effect<string, UserError> =>
  Effect.gen(function* () {
    // Find the user
    const user = yield* findUser(id);

    // Check if user is active
    const active = yield* isActive(user);
    if (!active) {
      return yield* Effect.fail("UserIsInactive" as const);
    }

    // Check if user is admin
    const admin = yield* isAdmin(user);
    if (!admin) {
      return yield* Effect.fail("UserIsNotAdmin" as const);
    }

    // Success case
    return `Welcome, admin user #${user.id}!`;
  });

// We can then handle the specific failures in a type-safe way.
const handled = program(123).pipe(
  Effect.match({
    onFailure: (error) => {
      switch (error) {
        case "UserIsNotAdmin":
          return "Access denied: requires admin role.";
        case "UserIsInactive":
          return "Access denied: user is not active.";
        case "DbError":
          return "Error: could not find user.";
        default:
          return `Unknown error: ${error}`;
      }
    },
    onSuccess: (result) => result
  })
);

// Run the program
Effect.runPromise(handled).then(console.log);
```

---

## Control Repetition with Schedule
**Rule:** Use Schedule to create composable policies for controlling the repetition and retrying of effects.

### Example
This example demonstrates composition by creating a common, robust retry policy: exponential backoff with jitter, limited to 5 attempts.

```typescript
import { Effect, Schedule, Duration } from "effect"

// A simple effect that can fail
const flakyEffect = Effect.try({
  try: () => {
    if (Math.random() > 0.2) {
      throw new Error("Transient error")
    }
    return "Operation succeeded!"
  },
  catch: (error: unknown) => {
    Effect.logInfo("Operation failed, retrying...")
    return error
  }
})

// --- Building a Composable Schedule ---

// 1. Start with a base exponential backoff (100ms, 200ms, 400ms...)
const exponentialBackoff = Schedule.exponential("100 millis")

// 2. Add random jitter to avoid thundering herd problems
const withJitter = Schedule.jittered(exponentialBackoff)

// 3. Limit the schedule to a maximum of 5 repetitions
const limitedWithJitter = Schedule.compose(
  withJitter,
  Schedule.recurs(5)
)

// --- Using the Schedule ---
const program = Effect.gen(function* () {
  yield* Effect.logInfo("Starting operation...")
  const result = yield* Effect.retry(flakyEffect, limitedWithJitter)
  yield* Effect.logInfo(`Final result: ${result}`)
})

// Run the program
Effect.runPromise(program)
```

---

## Define Type-Safe Errors with Data.TaggedError
**Rule:** Define type-safe errors with Data.TaggedError.

### Example
```typescript
import { Data, Effect } from "effect"

// Define our tagged error type
class DatabaseError extends Data.TaggedError("DatabaseError")<{
  readonly cause: unknown
}> {}

// Function that simulates a database error
const findUser = (id: number): Effect.Effect<{ id: number; name: string }, DatabaseError> =>
  Effect.gen(function* () {
    if (id < 0) {
      return yield* Effect.fail(new DatabaseError({ cause: "Invalid ID" }))
    }
    return { id, name: `User ${id}` }
  })

// Create a program that demonstrates error handling
const program = Effect.gen(function* () {
  // Try to find a valid user
  yield* Effect.logInfo("Looking up user 1...")
  yield* Effect.gen(function* () {
    const user = yield* findUser(1)
    yield* Effect.logInfo(`Found user: ${JSON.stringify(user)}`)
  }).pipe(
    Effect.catchAll((error) =>
      Effect.logInfo(`Error finding user: ${error._tag} - ${error.cause}`)
    )
  )

  // Try to find an invalid user
  yield* Effect.logInfo("\nLooking up user -1...")
  yield* Effect.gen(function* () {
    const user = yield* findUser(-1)
    yield* Effect.logInfo(`Found user: ${JSON.stringify(user)}`)
  }).pipe(
    Effect.catchTag("DatabaseError", (error) =>
      Effect.logInfo(`Database error: ${error._tag} - ${error.cause}`)
    )
  )
})

// Run the program
Effect.runPromise(program)
```

**Explanation:**  
Tagged errors allow you to handle errors in a type-safe, self-documenting way.

## Distinguish 'Not Found' from Errors
**Rule:** Use Effect<Option<A>> to distinguish between recoverable 'not found' cases and actual failures.

### Example
This function to find a user can fail if the database is down, or it can succeed but find no user. The return type ``Effect.Effect<Option.Option<User>, DatabaseError>`` makes this contract perfectly clear.

````typescript
import { Effect, Option, Data } from "effect"

interface User {
  id: number
  name: string
}
class DatabaseError extends Data.TaggedError("DatabaseError") {}

// This signature is extremely honest about its possible outcomes.
const findUserInDb = (
  id: number
): Effect.Effect<Option.Option<User>, DatabaseError> =>
  Effect.gen(function* () {
    // This could fail with a DatabaseError
    const dbResult = yield* Effect.try({
      try: () => (id === 1 ? { id: 1, name: "Paul" } : null),
      catch: () => new DatabaseError()
    })

    // We wrap the potentially null result in an Option
    return Option.fromNullable(dbResult)
  })

// The caller can now handle all three cases explicitly.
const program = (id: number) =>
  findUserInDb(id).pipe(
    Effect.flatMap((maybeUser) =>
      Option.match(maybeUser, {
        onNone: () =>
          Effect.logInfo(`Result: User with ID ${id} was not found.`),
        onSome: (user) =>
          Effect.logInfo(`Result: Found user ${user.name}.`)
      })
    ),
    Effect.catchAll((error) =>
      Effect.logInfo("Error: Could not connect to the database.")
    )
  )

// Run the program with different IDs
Effect.runPromise(
  Effect.gen(function* () {
    // Try with existing user
    yield* Effect.logInfo("Looking for user with ID 1...")
    yield* program(1)

    // Try with non-existent user
    yield* Effect.logInfo("\nLooking for user with ID 2...")
    yield* program(2)
  })
)
````

## Handle Errors with catchTag, catchTags, and catchAll
**Rule:** Handle errors with catchTag, catchTags, and catchAll.

### Example
```typescript
import { Data, Effect } from "effect";

// Define domain types
interface User {
  readonly id: string;
  readonly name: string;
}

// Define specific error types
class NetworkError extends Data.TaggedError("NetworkError")<{
  readonly url: string;
  readonly code: number;
}> { }

class ValidationError extends Data.TaggedError("ValidationError")<{
  readonly field: string;
  readonly message: string;
}> { }

class NotFoundError extends Data.TaggedError("NotFoundError")<{
  readonly id: string;
}> { }

// Define UserService
class UserService extends Effect.Service<UserService>()("UserService", {
  sync: () => ({
    // Fetch user data
    fetchUser: (
      id: string
    ): Effect.Effect<User, NetworkError | NotFoundError> =>
      Effect.gen(function* () {
        yield* Effect.logInfo(`Fetching user with id: ${id}`);

        if (id === "invalid") {
          const url = "/api/users/" + id;
          yield* Effect.logWarning(`Network error accessing: ${url}`);
          return yield* Effect.fail(new NetworkError({ url, code: 500 }));
        }

        if (id === "missing") {
          yield* Effect.logWarning(`User not found: ${id}`);
          return yield* Effect.fail(new NotFoundError({ id }));
        }

        const user = { id, name: "John Doe" };
        yield* Effect.logInfo(`Found user: ${JSON.stringify(user)}`);
        return user;
      }),

    // Validate user data
    validateUser: (user: User): Effect.Effect<string, ValidationError> =>
      Effect.gen(function* () {
        yield* Effect.logInfo(`Validating user: ${JSON.stringify(user)}`);

        if (user.name.length < 3) {
          yield* Effect.logWarning(
            `Validation failed: name too short for user ${user.id}`
          );
          return yield* Effect.fail(
            new ValidationError({ field: "name", message: "Name too short" })
          );
        }

        const message = `User ${user.name} is valid`;
        yield* Effect.logInfo(message);
        return message;
      }),
  }),
}) { }

// Compose operations with error handling using catchTags
const processUser = (
  userId: string
): Effect.Effect<string, never, UserService> =>
  Effect.gen(function* () {
    const userService = yield* UserService;

    yield* Effect.logInfo(`=== Processing user ID: ${userId} ===`);

    const result = yield* userService.fetchUser(userId).pipe(
      Effect.flatMap(userService.validateUser),
      // Handle different error types with specific recovery logic
      Effect.catchTags({
        NetworkError: (e) =>
          Effect.gen(function* () {
            const message = `Network error: ${e.code} for ${e.url}`;
            yield* Effect.logError(message);
            return message;
          }),
        NotFoundError: (e) =>
          Effect.gen(function* () {
            const message = `User ${e.id} not found`;
            yield* Effect.logWarning(message);
            return message;
          }),
        ValidationError: (e) =>
          Effect.gen(function* () {
            const message = `Invalid ${e.field}: ${e.message}`;
            yield* Effect.logWarning(message);
            return message;
          }),
      })
    );

    yield* Effect.logInfo(`Result: ${result}`);
    return result;
  });

// Test with different scenarios
const runTests = Effect.gen(function* () {
  yield* Effect.logInfo("=== Starting User Processing Tests ===");

  const testCases = ["valid", "invalid", "missing"];
  const results = yield* Effect.forEach(testCases, (id) => processUser(id));

  yield* Effect.logInfo("=== User Processing Tests Complete ===");
  return results;
});

// Run the program
Effect.runPromise(Effect.provide(runTests, UserService.Default));

```

**Explanation:**  
Use `catchTag` to handle specific error types in a type-safe, composable way.

## Handle Flaky Operations with Retries and Timeouts
**Rule:** Use Effect.retry and Effect.timeout to build resilience against slow or intermittently failing effects.

### Example
This program attempts to fetch data from a flaky API. It will retry the request up to 3 times with increasing delays if it fails. It will also give up entirely if any single attempt takes longer than 2 seconds.

```typescript
import { Data, Duration, Effect, Schedule } from "effect";

// Define domain types
interface ApiResponse {
  readonly data: string;
}

// Define error types
class ApiError extends Data.TaggedError("ApiError")<{
  readonly message: string;
  readonly attempt: number;
}> { }

class TimeoutError extends Data.TaggedError("TimeoutError")<{
  readonly duration: string;
  readonly attempt: number;
}> { }

// Define API service
class ApiService extends Effect.Service<ApiService>()(
  "ApiService",
  {
    sync: () => ({
      // Flaky API call that might fail or be slow
      fetchData: (): Effect.Effect<ApiResponse, ApiError | TimeoutError> =>
        Effect.gen(function* () {
          const attempt = Math.floor(Math.random() * 5) + 1;
          yield* Effect.logInfo(`Attempt ${attempt}: Making API call...`);

          if (Math.random() > 0.3) {
            yield* Effect.logWarning(`Attempt ${attempt}: API call failed`);
            return yield* Effect.fail(new ApiError({
              message: "API Error",
              attempt
            }));
          }

          const delay = Math.random() * 3000;
          yield* Effect.logInfo(`Attempt ${attempt}: API call will take ${delay.toFixed(0)}ms`);

          yield* Effect.sleep(Duration.millis(delay));

          const response = { data: "some important data" };
          yield* Effect.logInfo(`Attempt ${attempt}: API call succeeded with data: ${JSON.stringify(response)}`);
          return response;
        })
    })
  }
) { }

// Define retry policy: exponential backoff, up to 3 retries
const retryPolicy = Schedule.exponential(Duration.millis(100)).pipe(
  Schedule.compose(Schedule.recurs(3)),
  Schedule.tapInput((error: ApiError | TimeoutError) =>
    Effect.logWarning(`Retrying after error: ${error._tag} (Attempt ${error.attempt})`)
  )
);

// Create program with proper error handling
const program = Effect.gen(function* () {
  const api = yield* ApiService;

  yield* Effect.logInfo("=== Starting API calls with retry and timeout ===");

  // Make multiple test calls
  for (let i = 1; i <= 3; i++) {
    yield* Effect.logInfo(`\n--- Test Call ${i} ---`);

    const result = yield* api.fetchData().pipe(
      Effect.timeout(Duration.seconds(2)),
      Effect.catchTag("TimeoutException", () =>
        Effect.fail(new TimeoutError({ duration: "2 seconds", attempt: i }))
      ),
      Effect.retry(retryPolicy),
      Effect.catchTags({
        ApiError: (error) =>
          Effect.gen(function* () {
            yield* Effect.logError(`All retries failed: ${error.message} (Last attempt: ${error.attempt})`);
            return { data: "fallback data due to API error" } as ApiResponse;
          }),
        TimeoutError: (error) =>
          Effect.gen(function* () {
            yield* Effect.logError(`All retries timed out after ${error.duration} (Last attempt: ${error.attempt})`);
            return { data: "fallback data due to timeout" } as ApiResponse;
          })
      })
    );

    yield* Effect.logInfo(`Result: ${JSON.stringify(result)}`);
  }

  yield* Effect.logInfo("\n=== API calls complete ===");
});

// Run the program
Effect.runPromise(
  Effect.provide(program, ApiService.Default)
);
```

---

## Handle Unexpected Errors by Inspecting the Cause
**Rule:** Handle unexpected errors by inspecting the cause.

### Example
```typescript
import { Cause, Effect, Data, Schedule, Duration } from "effect";

// Define domain types
interface DatabaseConfig {
  readonly url: string;
}

interface DatabaseConnection {
  readonly success: true;
}

interface UserData {
  readonly id: string;
  readonly name: string;
}

// Define error types
class DatabaseError extends Data.TaggedError("DatabaseError")<{
  readonly operation: string;
  readonly details: string;
}> {}

class ValidationError extends Data.TaggedError("ValidationError")<{
  readonly field: string;
  readonly message: string;
}> {}

// Define database service
class DatabaseService extends Effect.Service<DatabaseService>()(
  "DatabaseService",
  {
    sync: () => ({
      // Connect to database with proper error handling
      connect: (config: DatabaseConfig): Effect.Effect<DatabaseConnection, DatabaseError> =>
        Effect.gen(function* () {
          yield* Effect.logInfo(`Connecting to database: ${config.url}`);
          
          if (!config.url) {
            const error = new DatabaseError({
              operation: "connect",
              details: "Missing URL"
            });
            yield* Effect.logError(`Database error: ${JSON.stringify(error)}`);
            return yield* Effect.fail(error);
          }
          
          // Simulate unexpected errors
          if (config.url === "invalid") {
            yield* Effect.logError("Invalid connection string");
            return yield* Effect.sync(() => {
              throw new Error("Failed to parse connection string");
            });
          }
          
          if (config.url === "timeout") {
            yield* Effect.logError("Connection timeout");
            return yield* Effect.sync(() => {
              throw new Error("Connection timed out");
            });
          }
          
          yield* Effect.logInfo("Database connection successful");
          return { success: true };
        })
    })
  }
) {}

// Define user service
class UserService extends Effect.Service<UserService>()(
  "UserService",
  {
    sync: () => ({
      // Parse user data with validation
      parseUser: (input: unknown): Effect.Effect<UserData, ValidationError> =>
        Effect.gen(function* () {
          yield* Effect.logInfo(`Parsing user data: ${JSON.stringify(input)}`);
          
          try {
            if (typeof input !== "object" || !input) {
              const error = new ValidationError({
                field: "input",
                message: "Invalid input type"
              });
              yield* Effect.logWarning(`Validation error: ${JSON.stringify(error)}`);
              throw error;
            }
            
            const data = input as Record<string, unknown>;
            
            if (typeof data.id !== "string" || typeof data.name !== "string") {
              const error = new ValidationError({
                field: "input",
                message: "Missing required fields"
              });
              yield* Effect.logWarning(`Validation error: ${JSON.stringify(error)}`);
              throw error;
            }
            
            const user = { id: data.id, name: data.name };
            yield* Effect.logInfo(`Successfully parsed user: ${JSON.stringify(user)}`);
            return user;
          } catch (e) {
            if (e instanceof ValidationError) {
              return yield* Effect.fail(e);
            }
            yield* Effect.logError(`Unexpected error: ${e instanceof Error ? e.message : String(e)}`);
            throw e;
          }
        })
    })
  }
) {}

// Define test service
class TestService extends Effect.Service<TestService>()(
  "TestService",
  {
    sync: () => {
      // Create instance methods
      const printCause = (prefix: string, cause: Cause.Cause<unknown>): Effect.Effect<void, never, never> =>
        Effect.gen(function* () {
          yield* Effect.logInfo(`\n=== ${prefix} ===`);
          
          if (Cause.isDie(cause)) {
            const defect = Cause.failureOption(cause);
            if (defect._tag === "Some") {
              const error = defect.value as Error;
              yield* Effect.logError("Defect (unexpected error)");
              yield* Effect.logError(`Message: ${error.message}`);
              yield* Effect.logError(`Stack: ${error.stack?.split('\n')[1]?.trim() ?? 'N/A'}`);
            }
          } else if (Cause.isFailure(cause)) {
            const error = Cause.failureOption(cause);
            yield* Effect.logWarning("Expected failure");
            yield* Effect.logWarning(`Error: ${JSON.stringify(error)}`);
          }

          return Effect.succeed(void 0);
        });

      const runScenario = <E, A extends { [key: string]: any }>(
        name: string,
        program: Effect.Effect<A, E>
      ): Effect.Effect<void, never, never> =>
        Effect.gen(function* () {
          yield* Effect.logInfo(`\n=== Testing: ${name} ===`);
          
          type TestError = { readonly _tag: "error"; readonly cause: Cause.Cause<E> };
          
          const result = yield* Effect.catchAllCause(
            program,
            (cause) => Effect.succeed({ _tag: "error" as const, cause } as TestError)
          );
          
          if ("cause" in result) {
            yield* printCause("Error details", result.cause);
          } else {
            yield* Effect.logInfo(`Success: ${JSON.stringify(result)}`);
          }

          return Effect.succeed(void 0);
        });

      // Return bound methods
      return {
        printCause,
        runScenario
      };
    }
  }
) {}

// Create program with proper error handling
const program = Effect.gen(function* () {
  const db = yield* DatabaseService;
  const users = yield* UserService;
  const test = yield* TestService;
  
  yield* Effect.logInfo("=== Starting Error Handling Tests ===");
  
  // Test expected database errors
  yield* test.runScenario(
    "Expected database error",
    Effect.gen(function* () {
      const result = yield* Effect.retry(
        db.connect({ url: "" }),
        Schedule.exponential(100)
      ).pipe(
        Effect.timeout(Duration.seconds(5)),
        Effect.catchAll(() => Effect.fail("Connection timeout"))
      );
      return result;
    })
  );
  
  // Test unexpected connection errors
  yield* test.runScenario(
    "Unexpected connection error",
    Effect.gen(function* () {
      const result = yield* Effect.retry(
        db.connect({ url: "invalid" }),
        Schedule.recurs(3)
      ).pipe(
        Effect.catchAllCause(cause =>
          Effect.gen(function* () {
            yield* Effect.logError("Failed after 3 retries");
            yield* Effect.logError(Cause.pretty(cause));
            return yield* Effect.fail("Max retries exceeded");
          })
        )
      );
      return result;
    })
  );
  
  // Test user validation with recovery
  yield* test.runScenario(
    "Valid user data",
    Effect.gen(function* () {
      const result = yield* users.parseUser({ id: "1", name: "John" }).pipe(
        Effect.orElse(() => 
          Effect.succeed({ id: "default", name: "Default User" })
        )
      );
      return result;
    })
  );
  
  // Test concurrent error handling with timeout
  yield* test.runScenario(
    "Concurrent operations",
    Effect.gen(function* () {
      const results = yield* Effect.all([
        db.connect({ url: "" }).pipe(
          Effect.timeout(Duration.seconds(1)),
          Effect.catchAll(() => Effect.succeed({ success: true }))
        ),
        users.parseUser({ id: "invalid" }).pipe(
          Effect.timeout(Duration.seconds(1)),
          Effect.catchAll(() => Effect.succeed({ id: "timeout", name: "Timeout" }))
        )
      ], { concurrency: 2 });
      return results;
    })
  );
  
  yield* Effect.logInfo("\n=== Error Handling Tests Complete ===");

  return Effect.succeed(void 0);
});

// Run the program with all services
Effect.runPromise(
  Effect.provide(
    Effect.provide(
      Effect.provide(
        program,
        TestService.Default
      ),
      DatabaseService.Default
    ),
    UserService.Default
  )
);
```

**Explanation:**  
By inspecting the `Cause`, you can distinguish between expected and unexpected
failures, logging or escalating as appropriate.

## Leverage Effect's Built-in Structured Logging
**Rule:** Leverage Effect's built-in structured logging.

### Example
```typescript
import { Effect } from "effect";

const program = Effect.logDebug("Processing user", { userId: 123 });

// Run the program with debug logging enabled
Effect.runSync(
  program.pipe(
    Effect.tap(() => Effect.log("Debug logging enabled"))
  )
);
```

**Explanation:**  
Using Effect's logging system ensures your logs are structured, filterable,
and context-aware.

## Mapping Errors to Fit Your Domain
**Rule:** Use Effect.mapError to transform errors and create clean architectural boundaries between layers.

### Example
A `UserRepository` uses a `Database` service. The `Database` can fail with specific errors, but the `UserRepository` maps them to a single, generic `RepositoryError` before they are exposed to the rest of the application.

```typescript
import { Effect, Data } from "effect";

// Low-level, specific errors from the database layer
class ConnectionError extends Data.TaggedError("ConnectionError") {}
class QueryError extends Data.TaggedError("QueryError") {}

// A generic error for the repository layer
class RepositoryError extends Data.TaggedError("RepositoryError")<{
  readonly cause: unknown;
}> {}

// The inner service
const dbQuery = (): Effect.Effect<
  { name: string },
  ConnectionError | QueryError
> => Effect.fail(new ConnectionError());

// The outer service uses `mapError` to create a clean boundary.
// Its public signature only exposes `RepositoryError`.
const findUser = (): Effect.Effect<{ name: string }, RepositoryError> =>
  dbQuery().pipe(
    Effect.mapError((error) => new RepositoryError({ cause: error }))
  );

// Demonstrate the error mapping
const program = Effect.gen(function* () {
  yield* Effect.logInfo("Attempting to find user...");

  try {
    const user = yield* findUser();
    yield* Effect.logInfo(`Found user: ${user.name}`);
  } catch (error) {
    yield* Effect.logInfo("This won't be reached due to Effect error handling");
  }
}).pipe(
  Effect.catchAll((error) =>
    Effect.gen(function* () {
      if (error instanceof RepositoryError) {
        yield* Effect.logInfo(`Repository error occurred: ${error._tag}`);
        if (error.cause instanceof ConnectionError || error.cause instanceof QueryError) {
          yield* Effect.logInfo(`Original cause: ${error.cause._tag}`);
        }
      } else {
        yield* Effect.logInfo(`Unexpected error: ${error}`);
      }
    })
  )
);

Effect.runPromise(program);

```

---

## Model Optional Values Safely with Option
**Rule:** Use Option<A> to explicitly model values that may be absent, avoiding null or undefined.

### Example
A function that looks for a user in a database is a classic use case. It might find a user, or it might not. Returning an `Option<User>` makes this contract explicit and safe.

```typescript
import { Option } from "effect";

interface User {
  id: number;
  name: string;
}

const users: User[] = [
  { id: 1, name: "Paul" },
  { id: 2, name: "Alex" },
];

// This function safely returns an Option, not a User or null.
const findUserById = (id: number): Option.Option<User> => {
  const user = users.find((u) => u.id === id);
  return Option.fromNullable(user); // A useful helper for existing APIs
};

// The caller MUST handle both cases.
const greeting = (id: number): string =>
  findUserById(id).pipe(
    Option.match({
      onNone: () => "User not found.",
      onSome: (user) => `Welcome, ${user.name}!`,
    }),
  );

console.log(greeting(1)); // "Welcome, Paul!"
console.log(greeting(3)); // "User not found."
```

## Retry Operations Based on Specific Errors
**Rule:** Use predicate-based retry policies to retry an operation only for specific, recoverable errors.

### Example
This example simulates an API client that can fail with different, specific error types. The retry policy is configured to *only* retry on `ServerBusyError` and give up immediately on `NotFoundError`.

```typescript
import { Effect, Data, Schedule, Duration } from "effect";

// Define specific, tagged errors for our API client
class ServerBusyError extends Data.TaggedError("ServerBusyError") {}
class NotFoundError extends Data.TaggedError("NotFoundError") {}

let attemptCount = 0;

// A flaky API call that can fail in different ways
const flakyApiCall = Effect.try({
  try: () => {
    attemptCount++;
    const random = Math.random();

    if (attemptCount <= 2) {
      // First two attempts fail with ServerBusyError (retryable)
      console.log(
        `Attempt ${attemptCount}: API call failed - Server is busy. Retrying...`
      );
      throw new ServerBusyError();
    }

    // Third attempt succeeds
    console.log(`Attempt ${attemptCount}: API call succeeded!`);
    return { data: "success", attempt: attemptCount };
  },
  catch: (e) => e as ServerBusyError | NotFoundError,
});

// A predicate that returns true only for the error we want to retry
const isRetryableError = (e: ServerBusyError | NotFoundError) =>
  e._tag === "ServerBusyError";

// A policy that retries 3 times, but only if the error is retryable
const selectiveRetryPolicy = Schedule.recurs(3).pipe(
  Schedule.whileInput(isRetryableError),
  Schedule.addDelay(() => "100 millis")
);

const program = Effect.gen(function* () {
  yield* Effect.logInfo("=== Retry Based on Specific Errors Demo ===");

  try {
    const result = yield* flakyApiCall.pipe(Effect.retry(selectiveRetryPolicy));
    yield* Effect.logInfo(`Success: ${JSON.stringify(result)}`);
    return result;
  } catch (error) {
    yield* Effect.logInfo("This won't be reached due to Effect error handling");
    return null;
  }
}).pipe(
  Effect.catchAll((error) =>
    Effect.gen(function* () {
      if (error instanceof NotFoundError) {
        yield* Effect.logInfo("Failed with NotFoundError - not retrying");
      } else if (error instanceof ServerBusyError) {
        yield* Effect.logInfo("Failed with ServerBusyError after all retries");
      } else {
        yield* Effect.logInfo(`Failed with unexpected error: ${error}`);
      }
      return null;
    })
  )
);

// Also demonstrate a case where NotFoundError is not retried
const demonstrateNotFound = Effect.gen(function* () {
  yield* Effect.logInfo("\n=== Demonstrating Non-Retryable Error ===");

  const alwaysNotFound = Effect.fail(new NotFoundError());

  const result = yield* alwaysNotFound.pipe(
    Effect.retry(selectiveRetryPolicy),
    Effect.catchAll((error) =>
      Effect.gen(function* () {
        yield* Effect.logInfo(`NotFoundError was not retried: ${error._tag}`);
        return null;
      })
    )
  );

  return result;
});

Effect.runPromise(program.pipe(Effect.flatMap(() => demonstrateNotFound)));

```

---

